[2024-02-26 11:10:39] [INFO    ] discord.client: logging in using static token
[2024-02-26 11:10:39] [INFO    ] discord.gateway: Shard ID None has connected to Gateway (Session ID: a868f6ae9364d79d47ddda6b64fc5bcb).
[2024-02-26 11:10:43] [ERROR   ] discord.client: Ignoring exception in on_message
Traceback (most recent call last):
  File "/home/lion/miniconda3/envs/lion_bot_env/lib/python3.9/site-packages/discord/client.py", line 441, in _run_event
    await coro(*args, **kwargs)
  File "/home/lion/lion_bot/./bot/lion_bot.py", line 159, in on_message
    db_posts.insert_one(post)
  File "/home/lion/miniconda3/envs/lion_bot_env/lib/python3.9/site-packages/pymongo/collection.py", line 669, in insert_one
    self._insert_one(
  File "/home/lion/miniconda3/envs/lion_bot_env/lib/python3.9/site-packages/pymongo/collection.py", line 609, in _insert_one
    self.__database.client._retryable_write(acknowledged, _insert_command, session)
  File "/home/lion/miniconda3/envs/lion_bot_env/lib/python3.9/site-packages/pymongo/mongo_client.py", line 1523, in _retryable_write
    return self._retry_with_session(retryable, func, s, bulk)
  File "/home/lion/miniconda3/envs/lion_bot_env/lib/python3.9/site-packages/pymongo/mongo_client.py", line 1421, in _retry_with_session
    return self._retry_internal(
  File "/home/lion/miniconda3/envs/lion_bot_env/lib/python3.9/site-packages/pymongo/_csot.py", line 107, in csot_wrapper
    return func(self, *args, **kwargs)
  File "/home/lion/miniconda3/envs/lion_bot_env/lib/python3.9/site-packages/pymongo/mongo_client.py", line 1453, in _retry_internal
    return _ClientConnectionRetryable(
  File "/home/lion/miniconda3/envs/lion_bot_env/lib/python3.9/site-packages/pymongo/mongo_client.py", line 2315, in run
    return self._read() if self._is_read else self._write()
  File "/home/lion/miniconda3/envs/lion_bot_env/lib/python3.9/site-packages/pymongo/mongo_client.py", line 2423, in _write
    return self._func(self._session, conn, self._retryable)  # type: ignore
  File "/home/lion/miniconda3/envs/lion_bot_env/lib/python3.9/site-packages/pymongo/collection.py", line 597, in _insert_command
    result = conn.command(
  File "/home/lion/miniconda3/envs/lion_bot_env/lib/python3.9/site-packages/pymongo/helpers.py", line 322, in inner
    return func(*args, **kwargs)
  File "/home/lion/miniconda3/envs/lion_bot_env/lib/python3.9/site-packages/pymongo/pool.py", line 996, in command
    self._raise_connection_failure(error)
  File "/home/lion/miniconda3/envs/lion_bot_env/lib/python3.9/site-packages/pymongo/pool.py", line 968, in command
    return command(
  File "/home/lion/miniconda3/envs/lion_bot_env/lib/python3.9/site-packages/pymongo/network.py", line 151, in command
    request_id, msg, size, max_doc_size = message._op_msg(
  File "/home/lion/miniconda3/envs/lion_bot_env/lib/python3.9/site-packages/pymongo/message.py", line 762, in _op_msg
    return _op_msg_uncompressed(flags, command, identifier, docs, opts)
bson.errors.InvalidDocument: cannot encode object: <ClientUser id=1199041303221121025 name='Lion Bot' global_name=None bot=True verified=True mfa_enabled=False>, of type: <class 'discord.user.ClientUser'>
