[2024-03-11 17:08:29] [INFO    ] discord.client: logging in using static token
[2024-03-11 17:08:29] [INFO    ] discord.gateway: Shard ID None has connected to Gateway (Session ID: 47d9d1c6c7a083b909375d762c8499dd).
[2024-03-11 17:11:32] [ERROR   ] discord.app_commands.tree: Ignoring exception in command 'ck'
Traceback (most recent call last):
  File "/home/lion/miniconda3/envs/lion_bot_env/lib/python3.9/site-packages/discord/app_commands/commands.py", line 828, in _do_call
    return await self._callback(interaction, **params)  # type: ignore
  File "/home/lion/lion_bot/./bot/lion_bot.py", line 394, in ck
    if member != None:
UnboundLocalError: local variable 'member' referenced before assignment

The above exception was the direct cause of the following exception:

Traceback (most recent call last):
  File "/home/lion/miniconda3/envs/lion_bot_env/lib/python3.9/site-packages/discord/app_commands/tree.py", line 1248, in _call
    await command._invoke_with_namespace(interaction, namespace)
  File "/home/lion/miniconda3/envs/lion_bot_env/lib/python3.9/site-packages/discord/app_commands/commands.py", line 853, in _invoke_with_namespace
    return await self._do_call(interaction, transformed_values)
  File "/home/lion/miniconda3/envs/lion_bot_env/lib/python3.9/site-packages/discord/app_commands/commands.py", line 846, in _do_call
    raise CommandInvokeError(self, e) from e
discord.app_commands.errors.CommandInvokeError: Command 'ck' raised an exception: UnboundLocalError: local variable 'member' referenced before assignment
[2024-03-11 17:11:59] [ERROR   ] discord.app_commands.tree: Ignoring exception in command 'ck'
Traceback (most recent call last):
  File "/home/lion/miniconda3/envs/lion_bot_env/lib/python3.9/site-packages/discord/app_commands/commands.py", line 828, in _do_call
    return await self._callback(interaction, **params)  # type: ignore
  File "/home/lion/lion_bot/./bot/lion_bot.py", line 412, in ck
    member = ms.Member(result[0])
IndexError: list index out of range

The above exception was the direct cause of the following exception:

Traceback (most recent call last):
  File "/home/lion/miniconda3/envs/lion_bot_env/lib/python3.9/site-packages/discord/app_commands/tree.py", line 1248, in _call
    await command._invoke_with_namespace(interaction, namespace)
  File "/home/lion/miniconda3/envs/lion_bot_env/lib/python3.9/site-packages/discord/app_commands/commands.py", line 853, in _invoke_with_namespace
    return await self._do_call(interaction, transformed_values)
  File "/home/lion/miniconda3/envs/lion_bot_env/lib/python3.9/site-packages/discord/app_commands/commands.py", line 846, in _do_call
    raise CommandInvokeError(self, e) from e
discord.app_commands.errors.CommandInvokeError: Command 'ck' raised an exception: IndexError: list index out of range
